Workbook

Sheet Attendance_Report
A1: KHY-HENG ATTENDANCE SYSTEM - ATTENDANCE REPORT & ANALYTICS
A2: របាយការណ៍វត្តមាន ស្ថិតិក្រាហ្វិក និងតារាងវិភាគភាពយឺតយ៉ាវ (Attendance Analytics, Visual Charts & Late Tracking Table)
A4: TOTAL EMPLOYEES (បុគ្គលិកសរុប) | D4: LOGGED ATTENDANCE (វត្តមានកត់ត្រា) | G4: ON TIME (ទាន់ពេល) | J4: LATE ARRIVALS (ការមកយឺត) | M4: EARLY / ABSENT (ចេញមុន & អវត្តមាន)
A5: =COUNTA(Employees!A4:A50) -> 10 | D5: =COUNTA(Attendance_Daily!A4:A33) -> 30 | G5: =COUNTIF(Attendance_Daily!U4:U33, "On Time") -> 18 | J5: =COUNTIF(Attendance_Daily!S4:S33, ">0") -> 5 | M5: =COUNTIF(Attendance_Daily!U4:U33, "*Absent*") + COUNTIF(Attendance_Daily!T4:T33, ">0") -> 4
N8: Status Category | O8: Record Count
N9: On Time (ទាន់ពេល) | O9: =COUNTIF(Attendance_Daily!$U$4:$U$33, "On Time") -> 18
N10: Late (មកយឺត) | O10: =COUNTIF(Attendance_Daily!$S$4:$S$33, ">0") -> 5
N11: Early Leave (ចេញមុន) | O11: =COUNTIF(Attendance_Daily!$T$4:$T$33, ">0") -> 3
N12: Leave (ច្បាប់) | O12: =COUNTIF(Attendance_Daily!$U$4:$U$33, "*Leave*") -> 6
N13: Absent (អវត្តមាន) | O13: =COUNTIF(Attendance_Daily!$U$4:$U$33, "Absent") -> 1
A24: 1. LATE ATTENDANCE & PUNCTUALITY ANALYSIS TABLE (តារាងតាមដាន និងវិភាគភាពយឺតយ៉ាវរបស់បុគ្គលិក)
A25: Staff ID (អត្តលេខ) | B25: Employee Name (EN) | C25: Employee Name (KH) | D25: Department (ផ្នែក) | E25: Scheduled Days | F25: Late Count (ដងយឺត) | G25: Morning Late (នាទីព្រឹក) | H25: Afternoon Late (នាទីរសៀល) | I25: Total Late Mins (សរុបនាទីយឺត) | J25: Avg Late (មធ្យម/ដង) | K25: Exceeded Grace (>15m) | L25: Late Status / Action (កម្រិតចំណាត់ការ)
A26: =Employees!A4 -> EMP-001 | B26: =Employees!B4 -> Khoem Piseth | C26: =Employees!C4 -> ខឹម ពិសិដ្ឋ | D26: =Employees!E4 -> Information Technology | E26: =Settings!$B$11 -> 26 | F26: =COUNTIFS(Attendance_Daily!$D$4:$D$33, A26, Attendance_Daily!$S$4:$S$33, ">0") -> 0 | G26: =SUMIFS(Attendance_Daily!$O$4:$O$33, Attendance_Daily!$D$4:$D$33, A26) -> 0 | H26: =SUMIFS(Attendance_Daily!$Q$4:$Q$33, Attendance_Daily!$D$4:$D$33, A26) -> 0 | I26: =SUMIFS(Attendance_Daily!$S$4:$S$33, Attendance_Daily!$D$4:$D$33, A26) -> 0 | J26: =IF(F26>0, ROUND(I26/F26, 1), 0) -> 0 | K26: =COUNTIFS(Attendance_Daily!$D$4:$D$33, A26, Attendance_Daily!$S$4:$S$33, ">15") -> 0 | L26: =IF(I26=0, "Punctual / ទៀងទាត់",IF(F26<=1, "Acceptable / អនុគ្រោះ",IF(F26<=2, "Verbal Warning / ព្រមានផ្ទាល់មាត់","Formal Warning / ព្រមានជាលាយលក្ខណ៍អក្សរ"))) -> Punctual / ទៀងទាត់
A27: =Employees!A5 -> EMP-002 | B27: =Employees!B5 -> Keo Sophea | C27: =Employees!C5 -> កែវ សុភា | D27: =Employees!E5 -> Human Resources | E27: =Settings!$B$11 -> 26 | F27: =COUNTIFS(Attendance_Daily!$D$4:$D$33, A27, Attendance_Daily!$S$4:$S$33, ">0") -> 1 | G27: =SUMIFS(Attendance_Daily!$O$4:$O$33, Attendance_Daily!$D$4:$D$33, A27) -> 30 | H27: =SUMIFS(Attendance_Daily!$Q$4:$Q$33, Attendance_Daily!$D$4:$D$33, A27) -> 0 | I27: =SUMIFS(Attendance_Daily!$S$4:$S$33, Attendance_Daily!$D$4:$D$33, A27) -> 30 | J27: =IF(F27>0, ROUND(I27/F27, 1), 0) -> 30 | K27: =COUNTIFS(Attendance_Daily!$D$4:$D$33, A27, Attendance_Daily!$S$4:$S$33, ">15") -> 1 | L27: =IF(I27=0, "Punctual / ទៀងទាត់",IF(F27<=1, "Acceptable / អនុគ្រោះ",IF(F27<=2, "Verbal Warning / ព្រមានផ្ទាល់មាត់","Formal Warning / ព្រមានជាលាយលក្ខណ៍អក្សរ"))) -> Acceptable / អនុគ្រោះ
A28: =Employees!A6 -> EMP-003 | B28: =Employees!B6 -> Chan Dara | C28: =Employees!C6 -> ចាន់ ដារ៉ា | D28: =Employees!E6 -> Information Technology | E28: =Settings!$B$11 -> 26 | F28: =COUNTIFS(Attendance_Daily!$D$4:$D$33, A28, Attendance_Daily!$S$4:$S$33, ">0") -> 1 | G28: =SUMIFS(Attendance_Daily!$O$4:$O$33, Attendance_Daily!$D$4:$D$33, A28) -> 25 | H28: =SUMIFS(Attendance_Daily!$Q$4:$Q$33, Attendance_Daily!$D$4:$D$33, A28) -> 0 | I28: =SUMIFS(Attendance_Daily!$S$4:$S$33, Attendance_Daily!$D$4:$D$33, A28) -> 25 | J28: =IF(F28>0, ROUND(I28/F28, 1), 0) -> 25 | K28: =COUNTIFS(Attendance_Daily!$D$4:$D$33, A28, Attendance_Daily!$S$4:$S$33, ">15") -> 1 | L28: =IF(I28=0, "Punctual / ទៀងទាត់",IF(F28<=1, "Acceptable / អនុគ្រោះ",IF(F28<=2, "Verbal Warning / ព្រមានផ្ទាល់មាត់","Formal Warning / ព្រមានជាលាយលក្ខណ៍អក្សរ"))) -> Acceptable / អនុគ្រោះ
A29: =Employees!A7 -> EMP-004 | B29: =Employees!B7 -> Sok Chenda | C29: =Employees!C7 -> សុខ ចិន្តា | D29: =Employees!E7 -> Finance & Accounting | E29: =Settings!$B$11 -> 26 | F29: =COUNTIFS(Attendance_Daily!$D$4:$D$33, A29, Attendance_Daily!$S$4:$S$33, ">0") -> 1 | G29: =SUMIFS(Attendance_Daily!$O$4:$O$33, Attendance_Daily!$D$4:$D$33, A29) -> 20 | H29: =SUMIFS(Attendance_Daily!$Q$4:$Q$33, Attendance_Daily!$D$4:$D$33, A29) -> 0 | I29: =SUMIFS(Attendance_Daily!$S$4:$S$33, Attendance_Daily!$D$4:$D$33, A29) -> #VALUE! | J29: =IF(F29>0, ROUND(I29/F29, 1), 0) -> #VALUE! | K29: =COUNTIFS(Attendance_Daily!$D$4:$D$33, A29, Attendance_Daily!$S$4:$S$33, ">15") -> 1 | L29: =IF(I29=0, "Punctual / ទៀងទាត់",IF(F29<=1, "Acceptable / អនុគ្រោះ",IF(F29<=2, "Verbal Warning / ព្រមានផ្ទាល់មាត់","Formal Warning / ព្រមានជាលាយលក្ខណ៍អក្សរ"))) -> #VALUE!
A30: =Employees!A8 -> EMP-005 | B30: =Employees!B8 -> Meng Chhay | C30: =Employees!C8 -> ម៉េង ឆាយ | D30: =Employees!E8 -> Marketing & Operations | E30: =Settings!$B$11 -> 26 | F30: =COUNTIFS(Attendance_Daily!$D$4:$D$33, A30, Attendance_Daily!$S$4:$S$33, ">0") -> 1 | G30: =SUMIFS(Attendance_Daily!$O$4:$O$33, Attendance_Daily!$D$4:$D$33, A30) -> 0 | H30: =SUMIFS(Attendance_Daily!$Q$4:$Q$33, Attendance_Daily!$D$4:$D$33, A30) -> 25 | I30: =SUMIFS(Attendance_Daily!$S$4:$S$33, Attendance_Daily!$D$4:$D$33, A30) -> 25 | J30: =IF(F30>0, ROUND(I30/F30, 1), 0) -> 25 | K30: =COUNTIFS(Attendance_Daily!$D$4:$D$33, A30, Attendance_Daily!$S$4:$S$33, ">15") -> 1 | L30: =IF(I30=0, "Punctual / ទៀងទាត់",IF(F30<=1, "Acceptable / អនុគ្រោះ",IF(F30<=2, "Verbal Warning / ព្រមានផ្ទាល់មាត់","Formal Warning / ព្រមានជាលាយលក្ខណ៍អក្សរ"))) -> Acceptable / អនុគ្រោះ
A31: =Employees!A9 -> EMP-006 | B31: =Employees!B9 -> Vannak Bopha | C31: =Employees!C9 -> វណ្ណៈ បុប្ផា | D31: =Employees!E9 -> Human Resources | E31: =Settings!$B$11 -> 26 | F31: =COUNTIFS(Attendance_Daily!$D$4:$D$33, A31, Attendance_Daily!$S$4:$S$33, ">0") -> 1 | G31: =SUMIFS(Attendance_Daily!$O$4:$O$33, Attendance_Daily!$D$4:$D$33, A31) -> 20 | H31: =SUMIFS(Attendance_Daily!$Q$4:$Q$33, Attendance_Daily!$D$4:$D$33, A31) -> 0 | I31: =SUMIFS(Attendance_Daily!$S$4:$S$33, Attendance_Daily!$D$4:$D$33, A31) -> 20 | J31: =IF(F31>0, ROUND(I31/F31, 1), 0) -> 20 | K31: =COUNTIFS(Attendance_Daily!$D$4:$D$33, A31, Attendance_Daily!$S$4:$S$33, ">15") -> 1 | L31: =IF(I31=0, "Punctual / ទៀងទាត់",IF(F31<=1, "Acceptable / អនុគ្រោះ",IF(F31<=2, "Verbal Warning / ព្រមានផ្ទាល់មាត់","Formal Warning / ព្រមានជាលាយលក្ខណ៍អក្សរ"))) -> Acceptable / អនុគ្រោះ
A32: =Employees!A10 -> EMP-007 | B32: =Employees!B10 -> Rithy Visal | C32: =Employees!C10 -> រិទ្ធី វិសាល | D32: =Employees!E10 -> Information Technology | E32: =Settings!$B$11 -> 26 | F32: =COUNTIFS(Attendance_Daily!$D$4:$D$33, A32, Attendance_Daily!$S$4:$S$33, ">0") -> 0 | G32: =SUMIFS(Attendance_Daily!$O$4:$O$33, Attendance_Daily!$D$4:$D$33, A32) -> 0 | H32: =SUMIFS(Attendance_Daily!$Q$4:$Q$33, Attendance_Daily!$D$4:$D$33, A32) -> 0 | I32: =SUMIFS(Attendance_Daily!$S$4:$S$33, Attendance_Daily!$D$4:$D$33, A32) -> #VALUE! | J32: =IF(F32>0, ROUND(I32/F32, 1), 0) -> 0 | K32: =COUNTIFS(Attendance_Daily!$D$4:$D$33, A32, Attendance_Daily!$S$4:$S$33, ">15") -> 0 | L32: =IF(I32=0, "Punctual / ទៀងទាត់",IF(F32<=1, "Acceptable / អនុគ្រោះ",IF(F32<=2, "Verbal Warning / ព្រមានផ្ទាល់មាត់","Formal Warning / ព្រមានជាលាយលក្ខណ៍អក្សរ"))) -> #VALUE!
A33: =Employees!A11 -> EMP-008 | B33: =Employees!B11 -> Chhorn Sreyneang | C33: =Employees!C11 -> ឈន ស្រីនាង | D33: =Employees!E11 -> Finance & Accounting | E33: =Settings!$B$11 -> 26 | F33: =COUNTIFS(Attendance_Daily!$D$4:$D$33, A33, Attendance_Daily!$S$4:$S$33, ">0") -> 0 | G33: =SUMIFS(Attendance_Daily!$O$4:$O$33, Attendance_Daily!$D$4:$D$33, A33) -> 0 | H33: =SUMIFS(Attendance_Daily!$Q$4:$Q$33, Attendance_Daily!$D$4:$D$33, A33) -> 0 | I33: =SUMIFS(Attendance_Daily!$S$4:$S$33, Attendance_Daily!$D$4:$D$33, A33) -> #VALUE! | J33: =IF(F33>0, ROUND(I33/F33, 1), 0) -> 0 | K33: =COUNTIFS(Attendance_Daily!$D$4:$D$33, A33, Attendance_Daily!$S$4:$S$33, ">15") -> 0 | L33: =IF(I33=0, "Punctual / ទៀងទាត់",IF(F33<=1, "Acceptable / អនុគ្រោះ",IF(F33<=2, "Verbal Warning / ព្រមានផ្ទាល់មាត់","Formal Warning / ព្រមានជាលាយលក្ខណ៍អក្សរ"))) -> #VALUE!
A34: =Employees!A12 -> EMP-009 | B34: =Employees!B12 -> Long Kosal | C34: =Employees!C12 -> ឡុង កុសល | D34: =Employees!E12 -> Information Technology | E34: =Settings!$B$11 -> 26 | F34: =COUNTIFS(Attendance_Daily!$D$4:$D$33, A34, Attendance_Daily!$S$4:$S$33, ">0") -> 0 | G34: =SUMIFS(Attendance_Daily!$O$4:$O$33, Attendance_Daily!$D$4:$D$33, A34) -> 0 | H34: =SUMIFS(Attendance_Daily!$Q$4:$Q$33, Attendance_Daily!$D$4:$D$33, A34) -> 0 | I34: =SUMIFS(Attendance_Daily!$S$4:$S$33, Attendance_Daily!$D$4:$D$33, A34) -> #VALUE! | J34: =IF(F34>0, ROUND(I34/F34, 1), 0) -> 0 | K34: =COUNTIFS(Attendance_Daily!$D$4:$D$33, A34, Attendance_Daily!$S$4:$S$33, ">15") -> 0 | L34: =IF(I34=0, "Punctual / ទៀងទាត់",IF(F34<=1, "Acceptable / អនុគ្រោះ",IF(F34<=2, "Verbal Warning / ព្រមានផ្ទាល់មាត់","Formal Warning / ព្រមានជាលាយលក្ខណ៍អក្សរ"))) -> #VALUE!
A35: =Employees!A13 -> EMP-010 | B35: =Employees!B13 -> Tep Nimol | C35: =Employees!C13 -> ទេព និមល | D35: =Employees!E13 -> Marketing & Operations | E35: =Settings!$B$11 -> 26 | F35: =COUNTIFS(Attendance_Daily!$D$4:$D$33, A35, Attendance_Daily!$S$4:$S$33, ">0") -> 0 | G35: =SUMIFS(Attendance_Daily!$O$4:$O$33, Attendance_Daily!$D$4:$D$33, A35) -> 0 | H35: =SUMIFS(Attendance_Daily!$Q$4:$Q$33, Attendance_Daily!$D$4:$D$33, A35) -> 0 | I35: =SUMIFS(Attendance_Daily!$S$4:$S$33, Attendance_Daily!$D$4:$D$33, A35) -> 0 | J35: =IF(F35>0, ROUND(I35/F35, 1), 0) -> 0 | K35: =COUNTIFS(Attendance_Daily!$D$4:$D$33, A35, Attendance_Daily!$S$4:$S$33, ">15") -> 0 | L35: =IF(I35=0, "Punctual / ទៀងទាត់",IF(F35<=1, "Acceptable / អនុគ្រោះ",IF(F35<=2, "Verbal Warning / ព្រមានផ្ទាល់មាត់","Formal Warning / ព្រមានជាលាយលក្ខណ៍អក្សរ"))) -> Punctual / ទៀងទាត់
A36: TOTAL LATE (សរុប) | F36: =SUM(F26:F35) -> 5 | G36: =SUM(G26:G35) -> 95 | H36: =SUM(H26:H35) -> 25 | I36: =SUM(I26:I35) -> #VALUE! | K36: =SUM(K26:K35) -> 5
A38: 2. OVERALL ATTENDANCE SUMMARY TABLE (តារាងសង្ខេបវត្តមានទូទៅប្រចាំខែ)
A39: Staff ID (អត្តលេខ) | B39: Employee Name (EN) | C39: Employee Name (KH) | D39: Department (ផ្នែក) | E39: Scheduled Days | F39: Present Days (វត្តមាន) | G39: On Time (ទាន់ពេល) | H39: Late Count (ដងយឺត) | I39: Total Late Mins (នាទីយឺត) | J39: Early Count (ដងចេញមុន) | K39: Total Early Mins (នាទីចេញមុន) | L39: Leave Days (ច្បាប់) | M39: Absent Days (អវត្តមាន) | N39: Total Work Hours (ម៉ោងការងារ) | O39: Overtime Hours (OT)
A40: =Employees!A4 -> EMP-001 | B40: =Employees!B4 -> Khoem Piseth | C40: =Employees!C4 -> ខឹម ពិសិដ្ឋ | D40: =Employees!E4 -> Information Technology | E40: =Settings!$B$11 -> 26 | F40: =COUNTIFS(Attendance_Daily!$D$4:$D$33, A40, Attendance_Daily!$U$4:$U$33, "<>Absent", Attendance_Daily!$U$4:$U$33, "<>Leave") -> 3 | G40: =COUNTIFS(Attendance_Daily!$D$4:$D$33, A40, Attendance_Daily!$U$4:$U$33, "On Time") -> 3 | H40: =COUNTIFS(Attendance_Daily!$D$4:$D$33, A40, Attendance_Daily!$S$4:$S$33, ">0") -> 0 | I40: =SUMIFS(Attendance_Daily!$S$4:$S$33, Attendance_Daily!$D$4:$D$33, A40) -> 0 | J40: =COUNTIFS(Attendance_Daily!$D$4:$D$33, A40, Attendance_Daily!$T$4:$T$33, ">0") -> 0 | K40: =SUMIFS(Attendance_Daily!$T$4:$T$33, Attendance_Daily!$D$4:$D$33, A40) -> 0 | L40: =COUNTIFS(Attendance_Daily!$D$4:$D$33, A40, Attendance_Daily!$U$4:$U$33, "*Leave*") -> 0 | M40: =COUNTIFS(Attendance_Daily!$D$4:$D$33, A40, Attendance_Daily!$U$4:$U$33, "Absent") -> 0 | N40: =SUMIFS(Attendance_Daily!$N$4:$N$33, Attendance_Daily!$D$4:$D$33, A40) -> 25.19 | O40: =SUMIFS(Attendance_Daily!$V$4:$V$33, Attendance_Daily!$D$4:$D$33, A40) -> 0
A41: =Employees!A5 -> EMP-002 | B41: =Employees!B5 -> Keo Sophea | C41: =Employees!C5 -> កែវ សុភា | D41: =Employees!E5 -> Human Resources | E41: =Settings!$B$11 -> 26 | F41: =COUNTIFS(Attendance_Daily!$D$4:$D$33, A41, Attendance_Daily!$U$4:$U$33, "<>Absent", Attendance_Daily!$U$4:$U$33, "<>Leave") -> 3 | G41: =COUNTIFS(Attendance_Daily!$D$4:$D$33, A41, Attendance_Daily!$U$4:$U$33, "On Time") -> 2 | H41: =COUNTIFS(Attendance_Daily!$D$4:$D$33, A41, Attendance_Daily!$S$4:$S$33, ">0") -> 1 | I41: =SUMIFS(Attendance_Daily!$S$4:$S$33, Attendance_Daily!$D$4:$D$33, A41) -> 30 | J41: =COUNTIFS(Attendance_Daily!$D$4:$D$33, A41, Attendance_Daily!$T$4:$T$33, ">0") -> 0 | K41: =SUMIFS(Attendance_Daily!$T$4:$T$33, Attendance_Daily!$D$4:$D$33, A41) -> 0 | L41: =COUNTIFS(Attendance_Daily!$D$4:$D$33, A41, Attendance_Daily!$U$4:$U$33, "*Leave*") -> 0 | M41: =COUNTIFS(Attendance_Daily!$D$4:$D$33, A41, Attendance_Daily!$U$4:$U$33, "Absent") -> 0 | N41: =SUMIFS(Attendance_Daily!$N$4:$N$33, Attendance_Daily!$D$4:$D$33, A41) -> 23.76 | O41: =SUMIFS(Attendance_Daily!$V$4:$V$33, Attendance_Daily!$D$4:$D$33, A41) -> 0
A42: =Employees!A6 -> EMP-003 | B42: =Employees!B6 -> Chan Dara | C42: =Employees!C6 -> ចាន់ ដារ៉ា | D42: =Employees!E6 -> Information Technology | E42: =Settings!$B$11 -> 26 | F42: =COUNTIFS(Attendance_Daily!$D$4:$D$33, A42, Attendance_Daily!$U$4:$U$33, "<>Absent", Attendance_Daily!$U$4:$U$33, "<>Leave") -> 3 | G42: =COUNTIFS(Attendance_Daily!$D$4:$D$33, A42, Attendance_Daily!$U$4:$U$33, "On Time") -> 2 | H42: =COUNTIFS(Attendance_Daily!$D$4:$D$33, A42, Attendance_Daily!$S$4:$S$33, ">0") -> 1 | I42: =SUMIFS(Attendance_Daily!$S$4:$S$33, Attendance_Daily!$D$4:$D$33, A42) -> 25 | J42: =COUNTIFS(Attendance_Daily!$D$4:$D$33, A42, Attendance_Daily!$T$4:$T$33, ">0") -> 0 | K42: =SUMIFS(Attendance_Daily!$T$4:$T$33, Attendance_Daily!$D$4:$D$33, A42) -> 0 | L42: =COUNTIFS(Attendance_Daily!$D$4:$D$33, A42, Attendance_Daily!$U$4:$U$33, "*Leave*") -> 0 | M42: =COUNTIFS(Attendance_Daily!$D$4:$D$33, A42, Attendance_Daily!$U$4:$U$33, "Absent") -> 0 | N42: =SUMIFS(Attendance_Daily!$N$4:$N$33, Attendance_Daily!$D$4:$D$33, A42) -> 25.01 | O42: =SUMIFS(Attendance_Daily!$V$4:$V$33, Attendance_Daily!$D$4:$D$33, A42) -> 0.5
A43: =Employees!A7 -> EMP-004 | B43: =Employees!B7 -> Sok Chenda | C43: =Employees!C7 -> សុខ ចិន្តា | D43: =Employees!E7 -> Finance & Accounting | E43: =Settings!$B$11 -> 26 | F43: =COUNTIFS(Attendance_Daily!$D$4:$D$33, A43, Attendance_Daily!$U$4:$U$33, "<>Absent", Attendance_Daily!$U$4:$U$33, "<>Leave") -> 2 | G43: =COUNTIFS(Attendance_Daily!$D$4:$D$33, A43, Attendance_Daily!$U$4:$U$33, "On Time") -> 0 | H43: =COUNTIFS(Attendance_Daily!$D$4:$D$33, A43, Attendance_Daily!$S$4:$S$33, ">0") -> 1 | I43: =SUMIFS(Attendance_Daily!$S$4:$S$33, Attendance_Daily!$D$4:$D$33, A43) -> #VALUE! | J43: =COUNTIFS(Attendance_Daily!$D$4:$D$33, A43, Attendance_Daily!$T$4:$T$33, ">0") -> 1 | K43: =SUMIFS(Attendance_Daily!$T$4:$T$33, Attendance_Daily!$D$4:$D$33, A43) -> #VALUE! | L43: =COUNTIFS(Attendance_Daily!$D$4:$D$33, A43, Attendance_Daily!$U$4:$U$33, "*Leave*") -> 2 | M43: =COUNTIFS(Attendance_Daily!$D$4:$D$33, A43, Attendance_Daily!$U$4:$U$33, "Absent") -> 0 | N43: =SUMIFS(Attendance_Daily!$N$4:$N$33, Attendance_Daily!$D$4:$D$33, A43) -> 15.58 | O43: =SUMIFS(Attendance_Daily!$V$4:$V$33, Attendance_Daily!$D$4:$D$33, A43) -> 0
A44: =Employees!A8 -> EMP-005 | B44: =Employees!B8 -> Meng Chhay | C44: =Employees!C8 -> ម៉េង ឆាយ | D44: =Employees!E8 -> Marketing & Operations | E44: =Settings!$B$11 -> 26 | F44: =COUNTIFS(Attendance_Daily!$D$4:$D$33, A44, Attendance_Daily!$U$4:$U$33, "<>Absent", Attendance_Daily!$U$4:$U$33, "<>Leave") -> 3 | G44: =COUNTIFS(Attendance_Daily!$D$4:$D$33, A44, Attendance_Daily!$U$4:$U$33, "On Time") -> 1 | H44: =COUNTIFS(Attendance_Daily!$D$4:$D$33, A44, Attendance_Daily!$S$4:$S$33, ">0") -> 1 | I44: =SUMIFS(Attendance_Daily!$S$4:$S$33, Attendance_Daily!$D$4:$D$33, A44) -> 25 | J44: =COUNTIFS(Attendance_Daily!$D$4:$D$33, A44, Attendance_Daily!$T$4:$T$33, ">0") -> 1 | K44: =SUMIFS(Attendance_Daily!$T$4:$T$33, Attendance_Daily!$D$4:$D$33, A44) -> 30 | L44: =COUNTIFS(Attendance_Daily!$D$4:$D$33, A44, Attendance_Daily!$U$4:$U$33, "*Leave*") -> 1 | M44: =COUNTIFS(Attendance_Daily!$D$4:$D$33, A44, Attendance_Daily!$U$4:$U$33, "Absent") -> 0 | N44: =SUMIFS(Attendance_Daily!$N$4:$N$33, Attendance_Daily!$D$4:$D$33, A44) -> 23.25 | O44: =SUMIFS(Attendance_Daily!$V$4:$V$33, Attendance_Daily!$D$4:$D$33, A44) -> 0
A45: =Employees!A9 -> EMP-006 | B45: =Employees!B9 -> Vannak Bopha | C45: =Employees!C9 -> វណ្ណៈ បុប្ផា | D45: =Employees!E9 -> Human Resources | E45: =Settings!$B$11 -> 26 | F45: =COUNTIFS(Attendance_Daily!$D$4:$D$33, A45, Attendance_Daily!$U$4:$U$33, "<>Absent", Attendance_Daily!$U$4:$U$33, "<>Leave") -> 3 | G45: =COUNTIFS(Attendance_Daily!$D$4:$D$33, A45, Attendance_Daily!$U$4:$U$33, "On Time") -> 2 | H45: =COUNTIFS(Attendance_Daily!$D$4:$D$33, A45, Attendance_Daily!$S$4:$S$33, ">0") -> 1 | I45: =SUMIFS(Attendance_Daily!$S$4:$S$33, Attendance_Daily!$D$4:$D$33, A45) -> 20 | J45: =COUNTIFS(Attendance_Daily!$D$4:$D$33, A45, Attendance_Daily!$T$4:$T$33, ">0") -> 1 | K45: =SUMIFS(Attendance_Daily!$T$4:$T$33, Attendance_Daily!$D$4:$D$33, A45) -> 15 | L45: =COUNTIFS(Attendance_Daily!$D$4:$D$33, A45, Attendance_Daily!$U$4:$U$33, "*Leave*") -> 1 | M45: =COUNTIFS(Attendance_Daily!$D$4:$D$33, A45, Attendance_Daily!$U$4:$U$33, "Absent") -> 0 | N45: =SUMIFS(Attendance_Daily!$N$4:$N$33, Attendance_Daily!$D$4:$D$33, A45) -> 23.48 | O45: =SUMIFS(Attendance_Daily!$V$4:$V$33, Attendance_Daily!$D$4:$D$33, A45) -> 0
A46: =Employees!A10 -> EMP-007 | B46: =Employees!B10 -> Rithy Visal | C46: =Employees!C10 -> រិទ្ធី វិសាល | D46: =Employees!E10 -> Information Technology | E46: =Settings!$B$11 -> 26 | F46: =COUNTIFS(Attendance_Daily!$D$4:$D$33, A46, Attendance_Daily!$U$4:$U$33, "<>Absent", Attendance_Daily!$U$4:$U$33, "<>Leave") -> 2 | G46: =COUNTIFS(Attendance_Daily!$D$4:$D$33, A46, Attendance_Daily!$U$4:$U$33, "On Time") -> 1 | H46: =COUNTIFS(Attendance_Daily!$D$4:$D$33, A46, Attendance_Daily!$S$4:$S$33, ">0") -> 0 | I46: =SUMIFS(Attendance_Daily!$S$4:$S$33, Attendance_Daily!$D$4:$D$33, A46) -> #VALUE! | J46: =COUNTIFS(Attendance_Daily!$D$4:$D$33, A46, Attendance_Daily!$T$4:$T$33, ">0") -> 0 | K46: =SUMIFS(Attendance_Daily!$T$4:$T$33, Attendance_Daily!$D$4:$D$33, A46) -> #VALUE! | L46: =COUNTIFS(Attendance_Daily!$D$4:$D$33, A46, Attendance_Daily!$U$4:$U$33, "*Leave*") -> 1 | M46: =COUNTIFS(Attendance_Daily!$D$4:$D$33, A46, Attendance_Daily!$U$4:$U$33, "Absent") -> 0 | N46: =SUMIFS(Attendance_Daily!$N$4:$N$33, Attendance_Daily!$D$4:$D$33, A46) -> 12 | O46: =SUMIFS(Attendance_Daily!$V$4:$V$33, Attendance_Daily!$D$4:$D$33, A46) -> 0
A47: =Employees!A11 -> EMP-008 | B47: =Employees!B11 -> Chhorn Sreyneang | C47: =Employees!C11 -> ឈន ស្រីនាង | D47: =Employees!E11 -> Finance & Accounting | E47: =Settings!$B$11 -> 26 | F47: =COUNTIFS(Attendance_Daily!$D$4:$D$33, A47, Attendance_Daily!$U$4:$U$33, "<>Absent", Attendance_Daily!$U$4:$U$33, "<>Leave") -> 2 | G47: =COUNTIFS(Attendance_Daily!$D$4:$D$33, A47, Attendance_Daily!$U$4:$U$33, "On Time") -> 2 | H47: =COUNTIFS(Attendance_Daily!$D$4:$D$33, A47, Attendance_Daily!$S$4:$S$33, ">0") -> 0 | I47: =SUMIFS(Attendance_Daily!$S$4:$S$33, Attendance_Daily!$D$4:$D$33, A47) -> #VALUE! | J47: =COUNTIFS(Attendance_Daily!$D$4:$D$33, A47, Attendance_Daily!$T$4:$T$33, ">0") -> 0 | K47: =SUMIFS(Attendance_Daily!$T$4:$T$33, Attendance_Daily!$D$4:$D$33, A47) -> #VALUE! | L47: =COUNTIFS(Attendance_Daily!$D$4:$D$33, A47, Attendance_Daily!$U$4:$U$33, "*Leave*") -> 1 | M47: =COUNTIFS(Attendance_Daily!$D$4:$D$33, A47, Attendance_Daily!$U$4:$U$33, "Absent") -> 0 | N47: =SUMIFS(Attendance_Daily!$N$4:$N$33, Attendance_Daily!$D$4:$D$33, A47) -> 16.34 | O47: =SUMIFS(Attendance_Daily!$V$4:$V$33, Attendance_Daily!$D$4:$D$33, A47) -> 0
A48: =Employees!A12 -> EMP-009 | B48: =Employees!B12 -> Long Kosal | C48: =Employees!C12 -> ឡុង កុសល | D48: =Employees!E12 -> Information Technology | E48: =Settings!$B$11 -> 26 | F48: =COUNTIFS(Attendance_Daily!$D$4:$D$33, A48, Attendance_Daily!$U$4:$U$33, "<>Absent", Attendance_Daily!$U$4:$U$33, "<>Leave") -> 2 | G48: =COUNTIFS(Attendance_Daily!$D$4:$D$33, A48, Attendance_Daily!$U$4:$U$33, "On Time") -> 2 | H48: =COUNTIFS(Attendance_Daily!$D$4:$D$33, A48, Attendance_Daily!$S$4:$S$33, ">0") -> 0 | I48: =SUMIFS(Attendance_Daily!$S$4:$S$33, Attendance_Daily!$D$4:$D$33, A48) -> #VALUE! | J48: =COUNTIFS(Attendance_Daily!$D$4:$D$33, A48, Attendance_Daily!$T$4:$T$33, ">0") -> 0 | K48: =SUMIFS(Attendance_Daily!$T$4:$T$33, Attendance_Daily!$D$4:$D$33, A48) -> #VALUE! | L48: =COUNTIFS(Attendance_Daily!$D$4:$D$33, A48, Attendance_Daily!$U$4:$U$33, "*Leave*") -> 0 | M48: =COUNTIFS(Attendance_Daily!$D$4:$D$33, A48, Attendance_Daily!$U$4:$U$33, "Absent") -> 1 | N48: =SUMIFS(Attendance_Daily!$N$4:$N$33, Attendance_Daily!$D$4:$D$33, A48) -> 16.33 | O48: =SUMIFS(Attendance_Daily!$V$4:$V$33, Attendance_Daily!$D$4:$D$33, A48) -> 0
A49: =Employees!A13 -> EMP-010 | B49: =Employees!B13 -> Tep Nimol | C49: =Employees!C13 -> ទេព និមល | D49: =Employees!E13 -> Marketing & Operations | E49: =Settings!$B$11 -> 26 | F49: =COUNTIFS(Attendance_Daily!$D$4:$D$33, A49, Attendance_Daily!$U$4:$U$33, "<>Absent", Attendance_Daily!$U$4:$U$33, "<>Leave") -> 3 | G49: =COUNTIFS(Attendance_Daily!$D$4:$D$33, A49, Attendance_Daily!$U$4:$U$33, "On Time") -> 3 | H49: =COUNTIFS(Attendance_Daily!$D$4:$D$33, A49, Attendance_Daily!$S$4:$S$33, ">0") -> 0 | I49: =SUMIFS(Attendance_Daily!$S$4:$S$33, Attendance_Daily!$D$4:$D$33, A49) -> 0 | J49: =COUNTIFS(Attendance_Daily!$D$4:$D$33, A49, Attendance_Daily!$T$4:$T$33, ">0") -> 0 | K49: =SUMIFS(Attendance_Daily!$T$4:$T$33, Attendance_Daily!$D$4:$D$33, A49) -> 0 | L49: =COUNTIFS(Attendance_Daily!$D$4:$D$33, A49, Attendance_Daily!$U$4:$U$33, "*Leave*") -> 0 | M49: =COUNTIFS(Attendance_Daily!$D$4:$D$33, A49, Attendance_Daily!$U$4:$U$33, "Absent") -> 0 | N49: =SUMIFS(Attendance_Daily!$N$4:$N$33, Attendance_Daily!$D$4:$D$33, A49) -> 28.25 | O49: =SUMIFS(Attendance_Daily!$V$4:$V$33, Attendance_Daily!$D$4:$D$33, A49) -> 3.5
A50: OVERALL TOTAL (សរុបរួម) | F50: =SUM(F40:F49) -> 26 | G50: =SUM(G40:G49) -> 18 | H50: =SUM(H40:H49) -> 5 | I50: =SUM(I40:I49) -> #VALUE! | J50: =SUM(J40:J49) -> 3 | K50: =SUM(K40:K49) -> #VALUE! | L50: =SUM(L40:L49) -> 6 | M50: =SUM(M40:M49) -> 1 | ... O50: =SUM(O40:O49) -> 4

Sheet Settings
A1: KHY-HENG ATTENDANCE SYSTEM - SETTINGS & CONFIGURATION (ការកំណត់ប្រព័ន្ធ)
A3: COMPANY WORK HOURS & SHIFT RULES (ម៉ោងការងារស្តង់ដារក្រុមហ៊ុន) | F3: DEPARTMENTS (ផ្នែក)
A4: Parameter Name (ប៉ារ៉ាម៉ែត្រ) | B4: Value (តម្លៃ) | C4: Unit / Details (ខ្នាត / បរិយាយ) | D4: System Code | F4: Dept Code | G4: Department (EN / KH)
A5: Morning Shift Start (ម៉ោងចូលវេនព្រឹក) | B5: 0.33333333 | C5: HH:MM (Shift 1 In) | D5: shift_1_start | F5: IT | G5: Information Technology (បច្ចេកវិទ្យាព័ត៌មាន)
A6: Morning Shift End (ម៉ោងចេញវេនព្រឹក) | B6: 0.5 | C6: HH:MM (Shift 1 Out) | D6: shift_1_end | F6: HR | G6: Human Resources (ធនធានមនុស្ស)
A7: Afternoon Shift Start (ម៉ោងចូលវេនរសៀល) | B7: 0.54166667 | C7: HH:MM (Shift 2 In) | D7: shift_2_start | F7: FIN | G7: Finance & Accounting (ហិរញ្ញវត្ថុ និងគណនេយ្យ)
A8: Afternoon Shift End (ម៉ោងចេញវេនរសៀល) | B8: 0.70833333 | C8: HH:MM (Shift 2 Out) | D8: shift_2_end | F8: MKT | G8: Marketing & Operations (ទីផ្សារ និងប្រតិបត្តិការ)
A9: Late Grace Period (នាទីអនុគ្រោះយឺត) | B9: 15 | C9: Minutes (អនុគ្រោះយឺត ១៥នាទី) | D9: late_grace_minutes
A10: Standard Daily Work Hours (ម៉ោងការងារប្រចាំថ្ងៃ) | B10: 8 | C10: Hours / Day | D10: standard_daily_hours
A11: Standard Monthly Working Days (ថ្ងៃការងារប្រចាំខែ) | B11: 26 | C11: Days / Month | D11: standard_working_days
A14: LEAVE TYPES & ALLOWANCES (ប្រភេទច្បាប់ឈប់សម្រាក)
A15: Code | B15: Leave Type (EN) | C15: Leave Type (KH) | D15: Max Days / Year | E15: Paid / Unpaid
A16: AL | B16: Annual Leave | C16: ច្បាប់សម្រាកប្រចាំឆ្នាំ | D16: 18 | E16: Paid
A17: SL | B17: Sick Leave | C17: ច្បាប់ឈឺ | D17: 12 | E17: Paid
A18: PL | B18: Personal Leave | C18: ច្បាប់ផ្ទាល់ខ្លួន | D18: 7 | E18: Paid
A19: ML | B19: Maternity Leave | C19: ច្បាប់លំហែមាតុភាព | D19: 90 | E19: Paid (50%-100%)
A20: UL | B20: Unpaid Leave | C20: ច្បាប់គ្មានប្រាក់ឈ្នួល | D20: 30 | E20: Unpaid

Sheet Employees
A1: EMPLOYEE MASTER DIRECTORY (បញ្ជីឈ្មោះបុគ្គលិក)
A3: Staff ID (អត្តលេខ) | B3: Name in English (ឈ្មោះអង់គ្លេស) | C3: Name in Khmer (ឈ្មោះខ្មែរ) | D3: Gender (ភេទ) | E3: Department (ផ្នែក) | F3: Position (តួនាទី) | G3: Branch (សាខា) | H3: Shift 1 In | I3: Shift 1 Out | J3: Shift 2 In | K3: Shift 2 Out
A4: EMP-001 | B4: Khoem Piseth | C4: ខឹម ពិសិដ្ឋ | D4: Male | E4: Information Technology | F4: IT Manager | G4: Phnom Penh HQ | H4: 0.33333333 | I4: 0.5 | J4: 0.54166667 | K4: 0.70833333
A5: EMP-002 | B5: Keo Sophea | C5: កែវ សុភា | D5: Female | E5: Human Resources | F5: HR Manager | G5: Phnom Penh HQ | H5: 0.33333333 | I5: 0.5 | J5: 0.54166667 | K5: 0.70833333
A6: EMP-003 | B6: Chan Dara | C6: ចាន់ ដារ៉ា | D6: Male | E6: Information Technology | F6: Senior Software Engineer | G6: Phnom Penh HQ | H6: 0.33333333 | I6: 0.5 | J6: 0.54166667 | K6: 0.70833333
A7: EMP-004 | B7: Sok Chenda | C7: សុខ ចិន្តា | D7: Female | E7: Finance & Accounting | F7: Senior Accountant | G7: Phnom Penh HQ | H7: 0.33333333 | I7: 0.5 | J7: 0.54166667 | K7: 0.70833333
A8: EMP-005 | B8: Meng Chhay | C8: ម៉េង ឆាយ | D8: Male | E8: Marketing & Operations | F8: Marketing Lead | G8: Phnom Penh HQ | H8: 0.33333333 | I8: 0.5 | J8: 0.54166667 | K8: 0.70833333
A9: EMP-006 | B9: Vannak Bopha | C9: វណ្ណៈ បុប្ផា | D9: Female | E9: Human Resources | F9: HR Specialist | G9: Phnom Penh HQ | H9: 0.33333333 | I9: 0.5 | J9: 0.54166667 | K9: 0.70833333
A10: EMP-007 | B10: Rithy Visal | C10: រិទ្ធី វិសាល | D10: Male | E10: Information Technology | F10: UI/UX Designer | G10: Phnom Penh HQ | H10: 0.33333333 | I10: 0.5 | J10: 0.54166667 | K10: 0.70833333
A11: EMP-008 | B11: Chhorn Sreyneang | C11: ឈន ស្រីនាង | D11: Female | E11: Finance & Accounting | F11: Junior Accountant | G11: Phnom Penh HQ | H11: 0.33333333 | I11: 0.5 | J11: 0.54166667 | K11: 0.70833333
A12: EMP-009 | B12: Long Kosal | C12: ឡុង កុសល | D12: Male | E12: Information Technology | F12: Network Specialist | G12: Phnom Penh HQ | H12: 0.33333333 | I12: 0.5 | J12: 0.54166667 | K12: 0.70833333
A13: EMP-010 | B13: Tep Nimol | C13: ទេព និមល | D13: Female | E13: Marketing & Operations | F13: Operations Officer | G13: Phnom Penh HQ | H13: 0.33333333 | I13: 0.5 | J13: 0.54166667 | K13: 0.70833333

Sheet Leaves
A1: LEAVE REQUESTS & APPROVALS (ការសុំច្បាប់ និងការអនុម័ត)
A3: Leave ID | B3: Staff ID | C3: Employee Name (EN) | D3: Leave Type | E3: Date (កាលបរិច្ឆេទ) | F3: Duration (រយៈពេល) | G3: Amount Days | H3: Status (ស្ថានភាព) | I3: Reason / Remarks (មូលហេតុ)
A4: LV-2026-001 | B4: EMP-004 | C4: =IFERROR(VLOOKUP(B4, Employees!$A$4:$C$50, 2, FALSE), "-") -> Sok Chenda | D4: Annual Leave | E4: 46268 | F4: Full Day | G4: 1 | H4: Approved | I4: Family event
A5: LV-2026-002 | B5: EMP-007 | C5: =IFERROR(VLOOKUP(B5, Employees!$A$4:$C$50, 2, FALSE), "-") -> Rithy Visal | D5: Sick Leave | E5: 46268 | F5: Full Day | G5: 1 | H5: Approved | I5: Fever and medical checkup
A6: LV-2026-003 | B6: EMP-008 | C6: =IFERROR(VLOOKUP(B6, Employees!$A$4:$C$50, 2, FALSE), "-") -> Chhorn Sreyneang | D6: Sick Leave | E6: 46266 | F6: Full Day | G6: 1 | H6: Approved | I6: Medical leave approved

Sheet Attendance_Daily
A1: DAILY ATTENDANCE LOG & AUTOMATIC COMPUTATION (កំណត់ត្រាវត្តមានប្រចាំថ្ងៃ និងគណនារូបមន្តស្វ័យប្រវត្តិ)
A2: ✓ រូបមន្តគណនាស្វ័យប្រវត្តិតាមច្បាប់ការងារ: ម៉ោងចូលវេនព្រឹក 08:00 (អនុគ្រោះ 15 នាទី), ម៉ោងចេញវេនព្រឹក 12:00, ម៉ោងចូលវេនរសៀល 13:00 (អនុគ្រោះ 15 នាទី), ម៉ោងចេញវេនរសៀល 17:00
A3: No. | B3: Date (កាលបរិច្ឆេទ) | C3: Day of Week | D3: Staff ID (អត្តលេខ) | E3: Employee Name (EN) | F3: Employee Name (KH) | G3: Department (ផ្នែក) | H3: Check-in 1 (ព្រឹកចូល) | I3: Check-out 1 (ព្រឹកចេញ) | J3: Check-in 2 (រសៀលចូល) | K3: Check-out 2 (រសៀលចេញ) | L3: Shift 1 Hours (ម៉ោងវេន១) | M3: Shift 2 Hours (ម៉ោងវេន២) | N3: Total Hours (ម៉ោងសរុប) | O3: Late 1 (នាទីយឺតព្រឹក) | P3: Early 1 (នាទីចេញមុនព្រឹក) | Q3: Late 2 (នាទីយឺតរសៀល) | R3: Early 2 (នាទីចេញមុនរសៀល) | S3: Total Late (សរុបយឺត) | T3: Total Early (សរុបចេញមុន) | U3: Daily Status (ស្ថានភាព) | V3: Overtime (OT ម៉ោង) | W3: Note / Remarks (កំណត់សម្គាល់)
A4: 1 | B4: 46266 | C4: =TEXT(B4,"dddd") -> Tuesday | D4: EMP-001 | E4: =IFERROR(VLOOKUP(D4, Employees!$A$4:$F$50, 2, FALSE), "-") -> Khoem Piseth | F4: =IFERROR(VLOOKUP(D4, Employees!$A$4:$F$50, 3, FALSE), "-") -> ខឹម ពិសិដ្ឋ | G4: =IFERROR(VLOOKUP(D4, Employees!$A$4:$F$50, 5, FALSE), "-") -> Information Technology | H4: 0.32777778 | I4: 0.50138889 | J4: 0.53819444 | K4: 0.71527778 | L4: =IF(AND(H4<>"", I4<>""), ROUND(MAX(0, (I4-H4)*24), 2), 0) -> 4.17 | M4: =IF(AND(J4<>"", K4<>""), ROUND(MAX(0, (K4-J4)*24), 2), 0) -> 4.25 | N4: =L4+M4 -> 8.42 | O4: =IF(H4="","", IF(H4 > (Settings!$B$5 + Settings!$B$9/1440), ROUND((H4 - Settings!$B$5)*1440, 0), 0)) -> 0 | P4: =IF(I4="","", IF(I4 < Settings!$B$6, ROUND((Settings!$B$6 - I4)*1440, 0), 0)) -> 0 | Q4: =IF(J4="","", IF(J4 > (Settings!$B$7 + Settings!$B$9/1440), ROUND((J4 - Settings!$B$7)*1440, 0), 0)) -> 0 | R4: =IF(K4="","", IF(K4 < Settings!$B$8, ROUND((Settings!$B$8 - K4)*1440, 0), 0)) -> 0 | S4: =O4+Q4 -> 0 | T4: =P4+R4 -> 0 | U4: =IF(COUNTIFS(Leaves!$B:$B, D4, Leaves!$E:$E, B4, Leaves!$H:$H, "Approved")>0, "Leave",IF(AND(H4="", I4="", J4="", K4=""), "Absent",IF(OR(AND(H4<>"", I4=""), AND(H4="", I4<>""), AND(J4<>"", K4=""), AND(J4="", K4<>"")), "Incomplete Scan",IF(AND(S4>0, T4>0), "Late & Early Leave",IF(S4>0, "Late",IF(T4>0, "Early Leave", "On Time")))))) -> On Time | V4: 0 | W4: Normal on time
A5: 2 | B5: 46266 | C5: =TEXT(B5,"dddd") -> Tuesday | D5: EMP-002 | E5: =IFERROR(VLOOKUP(D5, Employees!$A$4:$F$50, 2, FALSE), "-") -> Keo Sophea | F5: =IFERROR(VLOOKUP(D5, Employees!$A$4:$F$50, 3, FALSE), "-") -> កែវ សុភា | G5: =IFERROR(VLOOKUP(D5, Employees!$A$4:$F$50, 5, FALSE), "-") -> Human Resources | H5: 0.33194444 | I5: 0.5 | J5: 0.54027778 | K5: 0.70972222 | L5: =IF(AND(H5<>"", I5<>""), ROUND(MAX(0, (I5-H5)*24), 2), 0) -> 4.03 | M5: =IF(AND(J5<>"", K5<>""), ROUND(MAX(0, (K5-J5)*24), 2), 0) -> 4.07 | N5: =L5+M5 -> 8.1 | O5: =IF(H5="","", IF(H5 > (Settings!$B$5 + Settings!$B$9/1440), ROUND((H5 - Settings!$B$5)*1440, 0), 0)) -> 0 | P5: =IF(I5="","", IF(I5 < Settings!$B$6, ROUND((Settings!$B$6 - I5)*1440, 0), 0)) -> 0 | Q5: =IF(J5="","", IF(J5 > (Settings!$B$7 + Settings!$B$9/1440), ROUND((J5 - Settings!$B$7)*1440, 0), 0)) -> 0 | R5: =IF(K5="","", IF(K5 < Settings!$B$8, ROUND((Settings!$B$8 - K5)*1440, 0), 0)) -> 0 | S5: =O5+Q5 -> 0 | T5: =P5+R5 -> 0 | U5: =IF(COUNTIFS(Leaves!$B:$B, D5, Leaves!$E:$E, B5, Leaves!$H:$H, "Approved")>0, "Leave",IF(AND(H5="", I5="", J5="", K5=""), "Absent",IF(OR(AND(H5<>"", I5=""), AND(H5="", I5<>""), AND(J5<>"", K5=""), AND(J5="", K5<>"")), "Incomplete Scan",IF(AND(S5>0, T5>0), "Late & Early Leave",IF(S5>0, "Late",IF(T5>0, "Early Leave", "On Time")))))) -> On Time | V5: 0 | W5: Normal on time
A6: 3 | B6: 46266 | C6: =TEXT(B6,"dddd") -> Tuesday | D6: EMP-003 | E6: =IFERROR(VLOOKUP(D6, Employees!$A$4:$F$50, 2, FALSE), "-") -> Chan Dara | F6: =IFERROR(VLOOKUP(D6, Employees!$A$4:$F$50, 3, FALSE), "-") -> ចាន់ ដារ៉ា | G6: =IFERROR(VLOOKUP(D6, Employees!$A$4:$F$50, 5, FALSE), "-") -> Information Technology | H6: 0.35069444 | I6: 0.50347222 | J6: 0.53958333 | K6: 0.72916667 | L6: =IF(AND(H6<>"", I6<>""), ROUND(MAX(0, (I6-H6)*24), 2), 0) -> 3.67 | M6: =IF(AND(J6<>"", K6<>""), ROUND(MAX(0, (K6-J6)*24), 2), 0) -> 4.55 | N6: =L6+M6 -> 8.22 | O6: =IF(H6="","", IF(H6 > (Settings!$B$5 + Settings!$B$9/1440), ROUND((H6 - Settings!$B$5)*1440, 0), 0)) -> 25 | P6: =IF(I6="","", IF(I6 < Settings!$B$6, ROUND((Settings!$B$6 - I6)*1440, 0), 0)) -> 0 | Q6: =IF(J6="","", IF(J6 > (Settings!$B$7 + Settings!$B$9/1440), ROUND((J6 - Settings!$B$7)*1440, 0), 0)) -> 0 | R6: =IF(K6="","", IF(K6 < Settings!$B$8, ROUND((Settings!$B$8 - K6)*1440, 0), 0)) -> 0 | S6: =O6+Q6 -> 25 | T6: =P6+R6 -> 0 | U6: =IF(COUNTIFS(Leaves!$B:$B, D6, Leaves!$E:$E, B6, Leaves!$H:$H, "Approved")>0, "Leave",IF(AND(H6="", I6="", J6="", K6=""), "Absent",IF(OR(AND(H6<>"", I6=""), AND(H6="", I6<>""), AND(J6<>"", K6=""), AND(J6="", K6<>"")), "Incomplete Scan",IF(AND(S6>0, T6>0), "Late & Early Leave",IF(S6>0, "Late",IF(T6>0, "Early Leave", "On Time")))))) -> Late | V6: 0.5 | W6: Morning traffic late
A7: 4 | B7: 46266 | C7: =TEXT(B7,"dddd") -> Tuesday | D7: EMP-004 | E7: =IFERROR(VLOOKUP(D7, Employees!$A$4:$F$50, 2, FALSE), "-") -> Sok Chenda | F7: =IFERROR(VLOOKUP(D7, Employees!$A$4:$F$50, 3, FALSE), "-") -> សុខ ចិន្តា | G7: =IFERROR(VLOOKUP(D7, Employees!$A$4:$F$50, 5, FALSE), "-") -> Finance & Accounting | H7: 0.32638889 | I7: 0.48611111 | J7: 0.53819444 | K7: 0.70833333 | L7: =IF(AND(H7<>"", I7<>""), ROUND(MAX(0, (I7-H7)*24), 2), 0) -> 3.83 | M7: =IF(AND(J7<>"", K7<>""), ROUND(MAX(0, (K7-J7)*24), 2), 0) -> 4.08 | N7: =L7+M7 -> 7.91 | O7: =IF(H7="","", IF(H7 > (Settings!$B$5 + Settings!$B$9/1440), ROUND((H7 - Settings!$B$5)*1440, 0), 0)) -> 0 | P7: =IF(I7="","", IF(I7 < Settings!$B$6, ROUND((Settings!$B$6 - I7)*1440, 0), 0)) -> 20 | Q7: =IF(J7="","", IF(J7 > (Settings!$B$7 + Settings!$B$9/1440), ROUND((J7 - Settings!$B$7)*1440, 0), 0)) -> 0 | R7: =IF(K7="","", IF(K7 < Settings!$B$8, ROUND((Settings!$B$8 - K7)*1440, 0), 0)) -> 0 | S7: =O7+Q7 -> 0 | T7: =P7+R7 -> 20 | U7: =IF(COUNTIFS(Leaves!$B:$B, D7, Leaves!$E:$E, B7, Leaves!$H:$H, "Approved")>0, "Leave",IF(AND(H7="", I7="", J7="", K7=""), "Absent",IF(OR(AND(H7<>"", I7=""), AND(H7="", I7<>""), AND(J7<>"", K7=""), AND(J7="", K7<>"")), "Incomplete Scan",IF(AND(S7>0, T7>0), "Late & Early Leave",IF(S7>0, "Late",IF(T7>0, "Early Leave", "On Time")))))) -> Early Leave | V7: 0 | W7: Early leave morning for errand
A8: 5 | B8: 46266 | C8: =TEXT(B8,"dddd") -> Tuesday | D8: EMP-005 | E8: =IFERROR(VLOOKUP(D8, Employees!$A$4:$F$50, 2, FALSE), "-") -> Meng Chhay | F8: =IFERROR(VLOOKUP(D8, Employees!$A$4:$F$50, 3, FALSE), "-") -> ម៉េង ឆាយ | G8: =IFERROR(VLOOKUP(D8, Employees!$A$4:$F$50, 5, FALSE), "-") -> Marketing & Operations | H8: 0.33680556 | I8: 0.5 | J8: 0.55902778 | K8: 0.71180556 | L8: =IF(AND(H8<>"", I8<>""), ROUND(MAX(0, (I8-H8)*24), 2), 0) -> 3.92 | M8: =IF(AND(J8<>"", K8<>""), ROUND(MAX(0, (K8-J8)*24), 2), 0) -> 3.67 | N8: =L8+M8 -> 7.59 | O8: =IF(H8="","", IF(H8 > (Settings!$B$5 + Settings!$B$9/1440), ROUND((H8 - Settings!$B$5)*1440, 0), 0)) -> 0 | P8: =IF(I8="","", IF(I8 < Settings!$B$6, ROUND((Settings!$B$6 - I8)*1440, 0), 0)) -> 0 | Q8: =IF(J8="","", IF(J8 > (Settings!$B$7 + Settings!$B$9/1440), ROUND((J8 - Settings!$B$7)*1440, 0), 0)) -> 25 | R8: =IF(K8="","", IF(K8 < Settings!$B$8, ROUND((Settings!$B$8 - K8)*1440, 0), 0)) -> 0 | S8: =O8+Q8 -> 25 | T8: =P8+R8 -> 0 | U8: =IF(COUNTIFS(Leaves!$B:$B, D8, Leaves!$E:$E, B8, Leaves!$H:$H, "Approved")>0, "Leave",IF(AND(H8="", I8="", J8="", K8=""), "Absent",IF(OR(AND(H8<>"", I8=""), AND(H8="", I8<>""), AND(J8<>"", K8=""), AND(J8="", K8<>"")), "Incomplete Scan",IF(AND(S8>0, T8>0), "Late & Early Leave",IF(S8>0, "Late",IF(T8>0, "Early Leave", "On Time")))))) -> Late | V8: 0 | W8: Late afternoon
A9: 6 | B9: 46266 | C9: =TEXT(B9,"dddd") -> Tuesday | D9: EMP-006 | E9: =IFERROR(VLOOKUP(D9, Employees!$A$4:$F$50, 2, FALSE), "-") -> Vannak Bopha | F9: =IFERROR(VLOOKUP(D9, Employees!$A$4:$F$50, 3, FALSE), "-") -> វណ្ណៈ បុប្ផា | G9: =IFERROR(VLOOKUP(D9, Employees!$A$4:$F$50, 5, FALSE), "-") -> Human Resources | H9: 0.34722222 | I9: 0.5 | J9: 0.54166667 | K9: 0.69791667 | L9: =IF(AND(H9<>"", I9<>""), ROUND(MAX(0, (I9-H9)*24), 2), 0) -> 3.67 | M9: =IF(AND(J9<>"", K9<>""), ROUND(MAX(0, (K9-J9)*24), 2), 0) -> 3.75 | N9: =L9+M9 -> 7.42 | O9: =IF(H9="","", IF(H9 > (Settings!$B$5 + Settings!$B$9/1440), ROUND((H9 - Settings!$B$5)*1440, 0), 0)) -> 20 | P9: =IF(I9="","", IF(I9 < Settings!$B$6, ROUND((Settings!$B$6 - I9)*1440, 0), 0)) -> 0 | Q9: =IF(J9="","", IF(J9 > (Settings!$B$7 + Settings!$B$9/1440), ROUND((J9 - Settings!$B$7)*1440, 0), 0)) -> 0 | R9: =IF(K9="","", IF(K9 < Settings!$B$8, ROUND((Settings!$B$8 - K9)*1440, 0), 0)) -> 15 | S9: =O9+Q9 -> 20 | T9: =P9+R9 -> 15 | U9: =IF(COUNTIFS(Leaves!$B:$B, D9, Leaves!$E:$E, B9, Leaves!$H:$H, "Approved")>0, "Leave",IF(AND(H9="", I9="", J9="", K9=""), "Absent",IF(OR(AND(H9<>"", I9=""), AND(H9="", I9<>""), AND(J9<>"", K9=""), AND(J9="", K9<>"")), "Incomplete Scan",IF(AND(S9>0, T9>0), "Late & Early Leave",IF(S9>0, "Late",IF(T9>0, "Early Leave", "On Time")))))) -> Late & Early Leave | V9: 0 | W9: Late morning & early leave afternoon
A10: 7 | B10: 46266 | C10: =TEXT(B10,"dddd") -> Tuesday | D10: EMP-007 | E10: =IFERROR(VLOOKUP(D10, Employees!$A$4:$F$50, 2, FALSE), "-") -> Rithy Visal | F10: =IFERROR(VLOOKUP(D10, Employees!$A$4:$F$50, 3, FALSE), "-") -> រិទ្ធី វិសាល | G10: =IFERROR(VLOOKUP(D10, Employees!$A$4:$F$50, 5, FALSE), "-") -> Information Technology | H10: 0.32986111 | J10: 0.54166667 | K10: 0.70833333 | L10: =IF(AND(H10<>"", I10<>""), ROUND(MAX(0, (I10-H10)*24), 2), 0) -> 0 | M10: =IF(AND(J10<>"", K10<>""), ROUND(MAX(0, (K10-J10)*24), 2), 0) -> 4 | N10: =L10+M10 -> 4 | O10: =IF(H10="","", IF(H10 > (Settings!$B$5 + Settings!$B$9/1440), ROUND((H10 - Settings!$B$5)*1440, 0), 0)) -> 0 | P10: =IF(I10="","", IF(I10 < Settings!$B$6, ROUND((Settings!$B$6 - I10)*1440, 0), 0)) | Q10: =IF(J10="","", IF(J10 > (Settings!$B$7 + Settings!$B$9/1440), ROUND((J10 - Settings!$B$7)*1440, 0), 0)) -> 0 | R10: =IF(K10="","", IF(K10 < Settings!$B$8, ROUND((Settings!$B$8 - K10)*1440, 0), 0)) -> 0 | S10: =O10+Q10 -> 0 | T10: =P10+R10 -> #VALUE! | U10: =IF(COUNTIFS(Leaves!$B:$B, D10, Leaves!$E:$E, B10, Leaves!$H:$H, "Approved")>0, "Leave",IF(AND(H10="", I10="", J10="", K10=""), "Absent",IF(OR(AND(H10<>"", I10=""), AND(H10="", I10<>""), AND(J10<>"", K10=""), AND(J10="", K10<>"")), "Incomplete Scan",IF(AND(S10>0, T10>0), "Late & Early Leave",IF(S10>0, "Late",IF(T10>0, "Early Leave", "On Time")))))) -> Incomplete Scan | V10: 0 | W10: Forgot morning check-out
A11: 8 | B11: 46266 | C11: =TEXT(B11,"dddd") -> Tuesday | D11: EMP-008 | E11: =IFERROR(VLOOKUP(D11, Employees!$A$4:$F$50, 2, FALSE), "-") -> Chhorn Sreyneang | F11: =IFERROR(VLOOKUP(D11, Employees!$A$4:$F$50, 3, FALSE), "-") -> ឈន ស្រីនាង | G11: =IFERROR(VLOOKUP(D11, Employees!$A$4:$F$50, 5, FALSE), "-") -> Finance & Accounting | L11: =IF(AND(H11<>"", I11<>""), ROUND(MAX(0, (I11-H11)*24), 2), 0) -> 0 | M11: =IF(AND(J11<>"", K11<>""), ROUND(MAX(0, (K11-J11)*24), 2), 0) -> 0 | N11: =L11+M11 -> 0 | O11: =IF(H11="","", IF(H11 > (Settings!$B$5 + Settings!$B$9/1440), ROUND((H11 - Settings!$B$5)*1440, 0), 0)) | P11: =IF(I11="","", IF(I11 < Settings!$B$6, ROUND((Settings!$B$6 - I11)*1440, 0), 0)) | Q11: =IF(J11="","", IF(J11 > (Settings!$B$7 + Settings!$B$9/1440), ROUND((J11 - Settings!$B$7)*1440, 0), 0)) | R11: =IF(K11="","", IF(K11 < Settings!$B$8, ROUND((Settings!$B$8 - K11)*1440, 0), 0)) | S11: =O11+Q11 -> #VALUE! | T11: =P11+R11 -> #VALUE! | U11: =IF(COUNTIFS(Leaves!$B:$B, D11, Leaves!$E:$E, B11, Leaves!$H:$H, "Approved")>0, "Leave",IF(AND(H11="", I11="", J11="", K11=""), "Absent",IF(OR(AND(H11<>"", I11=""), AND(H11="", I11<>""), AND(J11<>"", K11=""), AND(J11="", K11<>"")), "Incomplete Scan",IF(AND(S11>0, T11>0), "Late & Early Leave",IF(S11>0, "Late",IF(T11>0, "Early Leave", "On Time")))))) -> Leave | V11: 0 | W11: Sick leave (has approval in Leaves sheet)
A12: 9 | B12: 46266 | C12: =TEXT(B12,"dddd") -> Tuesday | D12: EMP-009 | E12: =IFERROR(VLOOKUP(D12, Employees!$A$4:$F$50, 2, FALSE), "-") -> Long Kosal | F12: =IFERROR(VLOOKUP(D12, Employees!$A$4:$F$50, 3, FALSE), "-") -> ឡុង កុសល | G12: =IFERROR(VLOOKUP(D12, Employees!$A$4:$F$50, 5, FALSE), "-") -> Information Technology | L12: =IF(AND(H12<>"", I12<>""), ROUND(MAX(0, (I12-H12)*24), 2), 0) -> 0 | M12: =IF(AND(J12<>"", K12<>""), ROUND(MAX(0, (K12-J12)*24), 2), 0) -> 0 | N12: =L12+M12 -> 0 | O12: =IF(H12="","", IF(H12 > (Settings!$B$5 + Settings!$B$9/1440), ROUND((H12 - Settings!$B$5)*1440, 0), 0)) | P12: =IF(I12="","", IF(I12 < Settings!$B$6, ROUND((Settings!$B$6 - I12)*1440, 0), 0)) | Q12: =IF(J12="","", IF(J12 > (Settings!$B$7 + Settings!$B$9/1440), ROUND((J12 - Settings!$B$7)*1440, 0), 0)) | R12: =IF(K12="","", IF(K12 < Settings!$B$8, ROUND((Settings!$B$8 - K12)*1440, 0), 0)) | S12: =O12+Q12 -> #VALUE! | T12: =P12+R12 -> #VALUE! | U12: =IF(COUNTIFS(Leaves!$B:$B, D12, Leaves!$E:$E, B12, Leaves!$H:$H, "Approved")>0, "Leave",IF(AND(H12="", I12="", J12="", K12=""), "Absent",IF(OR(AND(H12<>"", I12=""), AND(H12="", I12<>""), AND(J12<>"", K12=""), AND(J12="", K12<>"")), "Incomplete Scan",IF(AND(S12>0, T12>0), "Late & Early Leave",IF(S12>0, "Late",IF(T12>0, "Early Leave", "On Time")))))) -> Absent | V12: 0 | W12: Unexcused Absence
A13: 10 | B13: 46266 | C13: =TEXT(B13,"dddd") -> Tuesday | D13: EMP-010 | E13: =IFERROR(VLOOKUP(D13, Employees!$A$4:$F$50, 2, FALSE), "-") -> Tep Nimol | F13: =IFERROR(VLOOKUP(D13, Employees!$A$4:$F$50, 3, FALSE), "-") -> ទេព និមល | G13: =IFERROR(VLOOKUP(D13, Employees!$A$4:$F$50, 5, FALSE), "-") -> Marketing & Operations | H13: 0.32291667 | I13: 0.5 | J13: 0.53472222 | K13: 0.79166667 | L13: =IF(AND(H13<>"", I13<>""), ROUND(MAX(0, (I13-H13)*24), 2), 0) -> 4.25 | M13: =IF(AND(J13<>"", K13<>""), ROUND(MAX(0, (K13-J13)*24), 2), 0) -> 6.17 | N13: =L13+M13 -> 10.42 | O13: =IF(H13="","", IF(H13 > (Settings!$B$5 + Settings!$B$9/1440), ROUND((H13 - Settings!$B$5)*1440, 0), 0)) -> 0 | P13: =IF(I13="","", IF(I13 < Settings!$B$6, ROUND((Settings!$B$6 - I13)*1440, 0), 0)) -> 0 | Q13: =IF(J13="","", IF(J13 > (Settings!$B$7 + Settings!$B$9/1440), ROUND((J13 - Settings!$B$7)*1440, 0), 0)) -> 0 | R13: =IF(K13="","", IF(K13 < Settings!$B$8, ROUND((Settings!$B$8 - K13)*1440, 0), 0)) -> 0 | S13: =O13+Q13 -> 0 | T13: =P13+R13 -> 0 | U13: =IF(COUNTIFS(Leaves!$B:$B, D13, Leaves!$E:$E, B13, Leaves!$H:$H, "Approved")>0, "Leave",IF(AND(H13="", I13="", J13="", K13=""), "Absent",IF(OR(AND(H13<>"", I13=""), AND(H13="", I13<>""), AND(J13<>"", K13=""), AND(J13="", K13<>"")), "Incomplete Scan",IF(AND(S13>0, T13>0), "Late & Early Leave",IF(S13>0, "Late",IF(T13>0, "Early Leave", "On Time")))))) -> On Time | V13: 2 | W13: 2 hrs Overtime approved
A14: 11 | B14: 46267 | C14: =TEXT(B14,"dddd") -> Wednesday | D14: EMP-001 | E14: =IFERROR(VLOOKUP(D14, Employees!$A$4:$F$50, 2, FALSE), "-") -> Khoem Piseth | F14: =IFERROR(VLOOKUP(D14, Employees!$A$4:$F$50, 3, FALSE), "-") -> ខឹម ពិសិដ្ឋ | G14: =IFERROR(VLOOKUP(D14, Employees!$A$4:$F$50, 5, FALSE), "-") -> Information Technology | H14: 0.32638889 | I14: 0.50069444 | J14: 0.53611111 | K14: 0.71180556 | L14: =IF(AND(H14<>"", I14<>""), ROUND(MAX(0, (I14-H14)*24), 2), 0) -> 4.18 | M14: =IF(AND(J14<>"", K14<>""), ROUND(MAX(0, (K14-J14)*24), 2), 0) -> 4.22 | N14: =L14+M14 -> 8.4 | O14: =IF(H14="","", IF(H14 > (Settings!$B$5 + Settings!$B$9/1440), ROUND((H14 - Settings!$B$5)*1440, 0), 0)) -> 0 | P14: =IF(I14="","", IF(I14 < Settings!$B$6, ROUND((Settings!$B$6 - I14)*1440, 0), 0)) -> 0 | Q14: =IF(J14="","", IF(J14 > (Settings!$B$7 + Settings!$B$9/1440), ROUND((J14 - Settings!$B$7)*1440, 0), 0)) -> 0 | R14: =IF(K14="","", IF(K14 < Settings!$B$8, ROUND((Settings!$B$8 - K14)*1440, 0), 0)) -> 0 | S14: =O14+Q14 -> 0 | T14: =P14+R14 -> 0 | U14: =IF(COUNTIFS(Leaves!$B:$B, D14, Leaves!$E:$E, B14, Leaves!$H:$H, "Approved")>0, "Leave",IF(AND(H14="", I14="", J14="", K14=""), "Absent",IF(OR(AND(H14<>"", I14=""), AND(H14="", I14<>""), AND(J14<>"", K14=""), AND(J14="", K14<>"")), "Incomplete Scan",IF(AND(S14>0, T14>0), "Late & Early Leave",IF(S14>0, "Late",IF(T14>0, "Early Leave", "On Time")))))) -> On Time | V14: 0 | W14: On time
A15: 12 | B15: 46267 | C15: =TEXT(B15,"dddd") -> Wednesday | D15: EMP-002 | E15: =IFERROR(VLOOKUP(D15, Employees!$A$4:$F$50, 2, FALSE), "-") -> Keo Sophea | F15: =IFERROR(VLOOKUP(D15, Employees!$A$4:$F$50, 3, FALSE), "-") -> កែវ សុភា | G15: =IFERROR(VLOOKUP(D15, Employees!$A$4:$F$50, 5, FALSE), "-") -> Human Resources | H15: 0.32986111 | I15: 0.5 | J15: 0.53819444 | K15: 0.70833333 | L15: =IF(AND(H15<>"", I15<>""), ROUND(MAX(0, (I15-H15)*24), 2), 0) -> 4.08 | M15: =IF(AND(J15<>"", K15<>""), ROUND(MAX(0, (K15-J15)*24), 2), 0) -> 4.08 | N15: =L15+M15 -> 8.16 | O15: =IF(H15="","", IF(H15 > (Settings!$B$5 + Settings!$B$9/1440), ROUND((H15 - Settings!$B$5)*1440, 0), 0)) -> 0 | P15: =IF(I15="","", IF(I15 < Settings!$B$6, ROUND((Settings!$B$6 - I15)*1440, 0), 0)) -> 0 | Q15: =IF(J15="","", IF(J15 > (Settings!$B$7 + Settings!$B$9/1440), ROUND((J15 - Settings!$B$7)*1440, 0), 0)) -> 0 | R15: =IF(K15="","", IF(K15 < Settings!$B$8, ROUND((Settings!$B$8 - K15)*1440, 0), 0)) -> 0 | S15: =O15+Q15 -> 0 | T15: =P15+R15 -> 0 | U15: =IF(COUNTIFS(Leaves!$B:$B, D15, Leaves!$E:$E, B15, Leaves!$H:$H, "Approved")>0, "Leave",IF(AND(H15="", I15="", J15="", K15=""), "Absent",IF(OR(AND(H15<>"", I15=""), AND(H15="", I15<>""), AND(J15<>"", K15=""), AND(J15="", K15<>"")), "Incomplete Scan",IF(AND(S15>0, T15>0), "Late & Early Leave",IF(S15>0, "Late",IF(T15>0, "Early Leave", "On Time")))))) -> On Time | V15: 0 | W15: On time
A16: 13 | B16: 46267 | C16: =TEXT(B16,"dddd") -> Wednesday | D16: EMP-003 | E16: =IFERROR(VLOOKUP(D16, Employees!$A$4:$F$50, 2, FALSE), "-") -> Chan Dara | F16: =IFERROR(VLOOKUP(D16, Employees!$A$4:$F$50, 3, FALSE), "-") -> ចាន់ ដារ៉ា | G16: =IFERROR(VLOOKUP(D16, Employees!$A$4:$F$50, 5, FALSE), "-") -> Information Technology | H16: 0.325 | I16: 0.5 | J16: 0.53472222 | K16: 0.71875 | L16: =IF(AND(H16<>"", I16<>""), ROUND(MAX(0, (I16-H16)*24), 2), 0) -> 4.2 | M16: =IF(AND(J16<>"", K16<>""), ROUND(MAX(0, (K16-J16)*24), 2), 0) -> 4.42 | N16: =L16+M16 -> 8.62 | O16: =IF(H16="","", IF(H16 > (Settings!$B$5 + Settings!$B$9/1440), ROUND((H16 - Settings!$B$5)*1440, 0), 0)) -> 0 | P16: =IF(I16="","", IF(I16 < Settings!$B$6, ROUND((Settings!$B$6 - I16)*1440, 0), 0)) -> 0 | Q16: =IF(J16="","", IF(J16 > (Settings!$B$7 + Settings!$B$9/1440), ROUND((J16 - Settings!$B$7)*1440, 0), 0)) -> 0 | R16: =IF(K16="","", IF(K16 < Settings!$B$8, ROUND((Settings!$B$8 - K16)*1440, 0), 0)) -> 0 | S16: =O16+Q16 -> 0 | T16: =P16+R16 -> 0 | U16: =IF(COUNTIFS(Leaves!$B:$B, D16, Leaves!$E:$E, B16, Leaves!$H:$H, "Approved")>0, "Leave",IF(AND(H16="", I16="", J16="", K16=""), "Absent",IF(OR(AND(H16<>"", I16=""), AND(H16="", I16<>""), AND(J16<>"", K16=""), AND(J16="", K16<>"")), "Incomplete Scan",IF(AND(S16>0, T16>0), "Late & Early Leave",IF(S16>0, "Late",IF(T16>0, "Early Leave", "On Time")))))) -> On Time | V16: 0 | W16: On time
A17: 14 | B17: 46267 | C17: =TEXT(B17,"dddd") -> Wednesday | D17: EMP-004 | E17: =IFERROR(VLOOKUP(D17, Employees!$A$4:$F$50, 2, FALSE), "-") -> Sok Chenda | F17: =IFERROR(VLOOKUP(D17, Employees!$A$4:$F$50, 3, FALSE), "-") -> សុខ ចិន្តា | G17: =IFERROR(VLOOKUP(D17, Employees!$A$4:$F$50, 5, FALSE), "-") -> Finance & Accounting | H17: 0.34722222 | I17: 0.5 | J17: 0.54166667 | K17: 0.70833333 | L17: =IF(AND(H17<>"", I17<>""), ROUND(MAX(0, (I17-H17)*24), 2), 0) -> 3.67 | M17: =IF(AND(J17<>"", K17<>""), ROUND(MAX(0, (K17-J17)*24), 2), 0) -> 4 | N17: =L17+M17 -> 7.67 | O17: =IF(H17="","", IF(H17 > (Settings!$B$5 + Settings!$B$9/1440), ROUND((H17 - Settings!$B$5)*1440, 0), 0)) -> 20 | P17: =IF(I17="","", IF(I17 < Settings!$B$6, ROUND((Settings!$B$6 - I17)*1440, 0), 0)) -> 0 | Q17: =IF(J17="","", IF(J17 > (Settings!$B$7 + Settings!$B$9/1440), ROUND((J17 - Settings!$B$7)*1440, 0), 0)) -> 0 | R17: =IF(K17="","", IF(K17 < Settings!$B$8, ROUND((Settings!$B$8 - K17)*1440, 0), 0)) -> 0 | S17: =O17+Q17 -> 20 | T17: =P17+R17 -> 0 | U17: =IF(COUNTIFS(Leaves!$B:$B, D17, Leaves!$E:$E, B17, Leaves!$H:$H, "Approved")>0, "Leave",IF(AND(H17="", I17="", J17="", K17=""), "Absent",IF(OR(AND(H17<>"", I17=""), AND(H17="", I17<>""), AND(J17<>"", K17=""), AND(J17="", K17<>"")), "Incomplete Scan",IF(AND(S17>0, T17>0), "Late & Early Leave",IF(S17>0, "Late",IF(T17>0, "Early Leave", "On Time")))))) -> Late | V17: 0 | W17: Late 5 mins after grace
A18: 15 | B18: 46267 | C18: =TEXT(B18,"dddd") -> Wednesday | D18: EMP-005 | E18: =IFERROR(VLOOKUP(D18, Employees!$A$4:$F$50, 2, FALSE), "-") -> Meng Chhay | F18: =IFERROR(VLOOKUP(D18, Employees!$A$4:$F$50, 3, FALSE), "-") -> ម៉េង ឆាយ | G18: =IFERROR(VLOOKUP(D18, Employees!$A$4:$F$50, 5, FALSE), "-") -> Marketing & Operations | H18: 0.33333333 | I18: 0.5 | J18: 0.54166667 | K18: 0.70833333 | L18: =IF(AND(H18<>"", I18<>""), ROUND(MAX(0, (I18-H18)*24), 2), 0) -> 4 | M18: =IF(AND(J18<>"", K18<>""), ROUND(MAX(0, (K18-J18)*24), 2), 0) -> 4 | N18: =L18+M18 -> 8 | O18: =IF(H18="","", IF(H18 > (Settings!$B$5 + Settings!$B$9/1440), ROUND((H18 - Settings!$B$5)*1440, 0), 0)) -> 0 | P18: =IF(I18="","", IF(I18 < Settings!$B$6, ROUND((Settings!$B$6 - I18)*1440, 0), 0)) -> 0 | Q18: =IF(J18="","", IF(J18 > (Settings!$B$7 + Settings!$B$9/1440), ROUND((J18 - Settings!$B$7)*1440, 0), 0)) -> 0 | R18: =IF(K18="","", IF(K18 < Settings!$B$8, ROUND((Settings!$B$8 - K18)*1440, 0), 0)) -> 0 | S18: =O18+Q18 -> 0 | T18: =P18+R18 -> 0 | U18: =IF(COUNTIFS(Leaves!$B:$B, D18, Leaves!$E:$E, B18, Leaves!$H:$H, "Approved")>0, "Leave",IF(AND(H18="", I18="", J18="", K18=""), "Absent",IF(OR(AND(H18<>"", I18=""), AND(H18="", I18<>""), AND(J18<>"", K18=""), AND(J18="", K18<>"")), "Incomplete Scan",IF(AND(S18>0, T18>0), "Late & Early Leave",IF(S18>0, "Late",IF(T18>0, "Early Leave", "On Time")))))) -> On Time | V18: 0 | W18: On time
A19: 16 | B19: 46267 | C19: =TEXT(B19,"dddd") -> Wednesday | D19: EMP-006 | E19: =IFERROR(VLOOKUP(D19, Employees!$A$4:$F$50, 2, FALSE), "-") -> Vannak Bopha | F19: =IFERROR(VLOOKUP(D19, Employees!$A$4:$F$50, 3, FALSE), "-") -> វណ្ណៈ បុប្ផា | G19: =IFERROR(VLOOKUP(D19, Employees!$A$4:$F$50, 5, FALSE), "-") -> Human Resources | H19: 0.33333333 | I19: 0.5 | J19: 0.54166667 | K19: 0.70833333 | L19: =IF(AND(H19<>"", I19<>""), ROUND(MAX(0, (I19-H19)*24), 2), 0) -> 4 | M19: =IF(AND(J19<>"", K19<>""), ROUND(MAX(0, (K19-J19)*24), 2), 0) -> 4 | N19: =L19+M19 -> 8 | O19: =IF(H19="","", IF(H19 > (Settings!$B$5 + Settings!$B$9/1440), ROUND((H19 - Settings!$B$5)*1440, 0), 0)) -> 0 | P19: =IF(I19="","", IF(I19 < Settings!$B$6, ROUND((Settings!$B$6 - I19)*1440, 0), 0)) -> 0 | Q19: =IF(J19="","", IF(J19 > (Settings!$B$7 + Settings!$B$9/1440), ROUND((J19 - Settings!$B$7)*1440, 0), 0)) -> 0 | R19: =IF(K19="","", IF(K19 < Settings!$B$8, ROUND((Settings!$B$8 - K19)*1440, 0), 0)) -> 0 | S19: =O19+Q19 -> 0 | T19: =P19+R19 -> 0 | U19: =IF(COUNTIFS(Leaves!$B:$B, D19, Leaves!$E:$E, B19, Leaves!$H:$H, "Approved")>0, "Leave",IF(AND(H19="", I19="", J19="", K19=""), "Absent",IF(OR(AND(H19<>"", I19=""), AND(H19="", I19<>""), AND(J19<>"", K19=""), AND(J19="", K19<>"")), "Incomplete Scan",IF(AND(S19>0, T19>0), "Late & Early Leave",IF(S19>0, "Late",IF(T19>0, "Early Leave", "On Time")))))) -> On Time | V19: 0 | W19: On time
A20: 17 | B20: 46267 | C20: =TEXT(B20,"dddd") -> Wednesday | D20: EMP-007 | E20: =IFERROR(VLOOKUP(D20, Employees!$A$4:$F$50, 2, FALSE), "-") -> Rithy Visal | F20: =IFERROR(VLOOKUP(D20, Employees!$A$4:$F$50, 3, FALSE), "-") -> រិទ្ធី វិសាល | G20: =IFERROR(VLOOKUP(D20, Employees!$A$4:$F$50, 5, FALSE), "-") -> Information Technology | H20: 0.33333333 | I20: 0.5 | J20: 0.54166667 | K20: 0.70833333 | L20: =IF(AND(H20<>"", I20<>""), ROUND(MAX(0, (I20-H20)*24), 2), 0) -> 4 | M20: =IF(AND(J20<>"", K20<>""), ROUND(MAX(0, (K20-J20)*24), 2), 0) -> 4 | N20: =L20+M20 -> 8 | O20: =IF(H20="","", IF(H20 > (Settings!$B$5 + Settings!$B$9/1440), ROUND((H20 - Settings!$B$5)*1440, 0), 0)) -> 0 | P20: =IF(I20="","", IF(I20 < Settings!$B$6, ROUND((Settings!$B$6 - I20)*1440, 0), 0)) -> 0 | Q20: =IF(J20="","", IF(J20 > (Settings!$B$7 + Settings!$B$9/1440), ROUND((J20 - Settings!$B$7)*1440, 0), 0)) -> 0 | R20: =IF(K20="","", IF(K20 < Settings!$B$8, ROUND((Settings!$B$8 - K20)*1440, 0), 0)) -> 0 | S20: =O20+Q20 -> 0 | T20: =P20+R20 -> 0 | U20: =IF(COUNTIFS(Leaves!$B:$B, D20, Leaves!$E:$E, B20, Leaves!$H:$H, "Approved")>0, "Leave",IF(AND(H20="", I20="", J20="", K20=""), "Absent",IF(OR(AND(H20<>"", I20=""), AND(H20="", I20<>""), AND(J20<>"", K20=""), AND(J20="", K20<>"")), "Incomplete Scan",IF(AND(S20>0, T20>0), "Late & Early Leave",IF(S20>0, "Late",IF(T20>0, "Early Leave", "On Time")))))) -> On Time | V20: 0 | W20: On time
A21: 18 | B21: 46267 | C21: =TEXT(B21,"dddd") -> Wednesday | D21: EMP-008 | E21: =IFERROR(VLOOKUP(D21, Employees!$A$4:$F$50, 2, FALSE), "-") -> Chhorn Sreyneang | F21: =IFERROR(VLOOKUP(D21, Employees!$A$4:$F$50, 3, FALSE), "-") -> ឈន ស្រីនាង | G21: =IFERROR(VLOOKUP(D21, Employees!$A$4:$F$50, 5, FALSE), "-") -> Finance & Accounting | H21: 0.33333333 | I21: 0.5 | J21: 0.54166667 | K21: 0.70833333 | L21: =IF(AND(H21<>"", I21<>""), ROUND(MAX(0, (I21-H21)*24), 2), 0) -> 4 | M21: =IF(AND(J21<>"", K21<>""), ROUND(MAX(0, (K21-J21)*24), 2), 0) -> 4 | N21: =L21+M21 -> 8 | O21: =IF(H21="","", IF(H21 > (Settings!$B$5 + Settings!$B$9/1440), ROUND((H21 - Settings!$B$5)*1440, 0), 0)) -> 0 | P21: =IF(I21="","", IF(I21 < Settings!$B$6, ROUND((Settings!$B$6 - I21)*1440, 0), 0)) -> 0 | Q21: =IF(J21="","", IF(J21 > (Settings!$B$7 + Settings!$B$9/1440), ROUND((J21 - Settings!$B$7)*1440, 0), 0)) -> 0 | R21: =IF(K21="","", IF(K21 < Settings!$B$8, ROUND((Settings!$B$8 - K21)*1440, 0), 0)) -> 0 | S21: =O21+Q21 -> 0 | T21: =P21+R21 -> 0 | U21: =IF(COUNTIFS(Leaves!$B:$B, D21, Leaves!$E:$E, B21, Leaves!$H:$H, "Approved")>0, "Leave",IF(AND(H21="", I21="", J21="", K21=""), "Absent",IF(OR(AND(H21<>"", I21=""), AND(H21="", I21<>""), AND(J21<>"", K21=""), AND(J21="", K21<>"")), "Incomplete Scan",IF(AND(S21>0, T21>0), "Late & Early Leave",IF(S21>0, "Late",IF(T21>0, "Early Leave", "On Time")))))) -> On Time | V21: 0 | W21: On time
A22: 19 | B22: 46267 | C22: =TEXT(B22,"dddd") -> Wednesday | D22: EMP-009 | E22: =IFERROR(VLOOKUP(D22, Employees!$A$4:$F$50, 2, FALSE), "-") -> Long Kosal | F22: =IFERROR(VLOOKUP(D22, Employees!$A$4:$F$50, 3, FALSE), "-") -> ឡុង កុសល | G22: =IFERROR(VLOOKUP(D22, Employees!$A$4:$F$50, 5, FALSE), "-") -> Information Technology | H22: 0.34027778 | I22: 0.5 | J22: 0.54166667 | K22: 0.70833333 | L22: =IF(AND(H22<>"", I22<>""), ROUND(MAX(0, (I22-H22)*24), 2), 0) -> 3.83 | M22: =IF(AND(J22<>"", K22<>""), ROUND(MAX(0, (K22-J22)*24), 2), 0) -> 4 | N22: =L22+M22 -> 7.83 | O22: =IF(H22="","", IF(H22 > (Settings!$B$5 + Settings!$B$9/1440), ROUND((H22 - Settings!$B$5)*1440, 0), 0)) -> 0 | P22: =IF(I22="","", IF(I22 < Settings!$B$6, ROUND((Settings!$B$6 - I22)*1440, 0), 0)) -> 0 | Q22: =IF(J22="","", IF(J22 > (Settings!$B$7 + Settings!$B$9/1440), ROUND((J22 - Settings!$B$7)*1440, 0), 0)) -> 0 | R22: =IF(K22="","", IF(K22 < Settings!$B$8, ROUND((Settings!$B$8 - K22)*1440, 0), 0)) -> 0 | S22: =O22+Q22 -> 0 | T22: =P22+R22 -> 0 | U22: =IF(COUNTIFS(Leaves!$B:$B, D22, Leaves!$E:$E, B22, Leaves!$H:$H, "Approved")>0, "Leave",IF(AND(H22="", I22="", J22="", K22=""), "Absent",IF(OR(AND(H22<>"", I22=""), AND(H22="", I22<>""), AND(J22<>"", K22=""), AND(J22="", K22<>"")), "Incomplete Scan",IF(AND(S22>0, T22>0), "Late & Early Leave",IF(S22>0, "Late",IF(T22>0, "Early Leave", "On Time")))))) -> On Time | V22: 0 | W22: Within 15m grace - On time
A23: 20 | B23: 46267 | C23: =TEXT(B23,"dddd") -> Wednesday | D23: EMP-010 | E23: =IFERROR(VLOOKUP(D23, Employees!$A$4:$F$50, 2, FALSE), "-") -> Tep Nimol | F23: =IFERROR(VLOOKUP(D23, Employees!$A$4:$F$50, 3, FALSE), "-") -> ទេព និមល | G23: =IFERROR(VLOOKUP(D23, Employees!$A$4:$F$50, 5, FALSE), "-") -> Marketing & Operations | H23: 0.32638889 | I23: 0.5 | J23: 0.54166667 | K23: 0.70833333 | L23: =IF(AND(H23<>"", I23<>""), ROUND(MAX(0, (I23-H23)*24), 2), 0) -> 4.17 | M23: =IF(AND(J23<>"", K23<>""), ROUND(MAX(0, (K23-J23)*24), 2), 0) -> 4 | N23: =L23+M23 -> 8.17 | O23: =IF(H23="","", IF(H23 > (Settings!$B$5 + Settings!$B$9/1440), ROUND((H23 - Settings!$B$5)*1440, 0), 0)) -> 0 | P23: =IF(I23="","", IF(I23 < Settings!$B$6, ROUND((Settings!$B$6 - I23)*1440, 0), 0)) -> 0 | Q23: =IF(J23="","", IF(J23 > (Settings!$B$7 + Settings!$B$9/1440), ROUND((J23 - Settings!$B$7)*1440, 0), 0)) -> 0 | R23: =IF(K23="","", IF(K23 < Settings!$B$8, ROUND((Settings!$B$8 - K23)*1440, 0), 0)) -> 0 | S23: =O23+Q23 -> 0 | T23: =P23+R23 -> 0 | U23: =IF(COUNTIFS(Leaves!$B:$B, D23, Leaves!$E:$E, B23, Leaves!$H:$H, "Approved")>0, "Leave",IF(AND(H23="", I23="", J23="", K23=""), "Absent",IF(OR(AND(H23<>"", I23=""), AND(H23="", I23<>""), AND(J23<>"", K23=""), AND(J23="", K23<>"")), "Incomplete Scan",IF(AND(S23>0, T23>0), "Late & Early Leave",IF(S23>0, "Late",IF(T23>0, "Early Leave", "On Time")))))) -> On Time | V23: 0 | W23: On time
A24: 21 | B24: 46268 | C24: =TEXT(B24,"dddd") -> Thursday | D24: EMP-001 | E24: =IFERROR(VLOOKUP(D24, Employees!$A$4:$F$50, 2, FALSE), "-") -> Khoem Piseth | F24: =IFERROR(VLOOKUP(D24, Employees!$A$4:$F$50, 3, FALSE), "-") -> ខឹម ពិសិដ្ឋ | G24: =IFERROR(VLOOKUP(D24, Employees!$A$4:$F$50, 5, FALSE), "-") -> Information Technology | H24: 0.32986111 | I24: 0.50347222 | J24: 0.54027778 | K24: 0.71527778 | L24: =IF(AND(H24<>"", I24<>""), ROUND(MAX(0, (I24-H24)*24), 2), 0) -> 4.17 | M24: =IF(AND(J24<>"", K24<>""), ROUND(MAX(0, (K24-J24)*24), 2), 0) -> 4.2 | N24: =L24+M24 -> 8.37 | O24: =IF(H24="","", IF(H24 > (Settings!$B$5 + Settings!$B$9/1440), ROUND((H24 - Settings!$B$5)*1440, 0), 0)) -> 0 | P24: =IF(I24="","", IF(I24 < Settings!$B$6, ROUND((Settings!$B$6 - I24)*1440, 0), 0)) -> 0 | Q24: =IF(J24="","", IF(J24 > (Settings!$B$7 + Settings!$B$9/1440), ROUND((J24 - Settings!$B$7)*1440, 0), 0)) -> 0 | R24: =IF(K24="","", IF(K24 < Settings!$B$8, ROUND((Settings!$B$8 - K24)*1440, 0), 0)) -> 0 | S24: =O24+Q24 -> 0 | T24: =P24+R24 -> 0 | U24: =IF(COUNTIFS(Leaves!$B:$B, D24, Leaves!$E:$E, B24, Leaves!$H:$H, "Approved")>0, "Leave",IF(AND(H24="", I24="", J24="", K24=""), "Absent",IF(OR(AND(H24<>"", I24=""), AND(H24="", I24<>""), AND(J24<>"", K24=""), AND(J24="", K24<>"")), "Incomplete Scan",IF(AND(S24>0, T24>0), "Late & Early Leave",IF(S24>0, "Late",IF(T24>0, "Early Leave", "On Time")))))) -> On Time | V24: 0 | W24: On time
... A26: 23 | B26: 46268 | C26: =TEXT(B26,"dddd") -> Thursday | D26: EMP-003 | E26: =IFERROR(VLOOKUP(D26, Employees!$A$4:$F$50, 2, FALSE), "-") -> Chan Dara | F26: =IFERROR(VLOOKUP(D26, Employees!$A$4:$F$50, 3, FALSE), "-") -> ចាន់ ដារ៉ា | G26: =IFERROR(VLOOKUP(D26, Employees!$A$4:$F$50, 5, FALSE), "-") -> Information Technology | H26: 0.32638889 | I26: 0.5 | J26: 0.54166667 | K26: 0.70833333 | L26: =IF(AND(H26<>"", I26<>""), ROUND(MAX(0, (I26-H26)*24), 2), 0) -> 4.17 | M26: =IF(AND(J26<>"", K26<>""), ROUND(MAX(0, (K26-J26)*24), 2), 0) -> 4 | N26: =L26+M26 -> 8.17 | O26: =IF(H26="","", IF(H26 > (Settings!$B$5 + Settings!$B$9/1440), ROUND((H26 - Settings!$B$5)*1440, 0), 0)) -> 0 | P26: =IF(I26="","", IF(I26 < Settings!$B$6, ROUND((Settings!$B$6 - I26)*1440, 0), 0)) -> 0 | Q26: =IF(J26="","", IF(J26 > (Settings!$B$7 + Settings!$B$9/1440), ROUND((J26 - Settings!$B$7)*1440, 0), 0)) -> 0 | R26: =IF(K26="","", IF(K26 < Settings!$B$8, ROUND((Settings!$B$8 - K26)*1440, 0), 0)) -> 0 | S26: =O26+Q26 -> 0 | T26: =P26+R26 -> 0 | U26: =IF(COUNTIFS(Leaves!$B:$B, D26, Leaves!$E:$E, B26, Leaves!$H:$H, "Approved")>0, "Leave",IF(AND(H26="", I26="", J26="", K26=""), "Absent",IF(OR(AND(H26<>"", I26=""), AND(H26="", I26<>""), AND(J26<>"", K26=""), AND(J26="", K26<>"")), "Incomplete Scan",IF(AND(S26>0, T26>0), "Late & Early Leave",IF(S26>0, "Late",IF(T26>0, "Early Leave", "On Time")))))) -> On Time | V26: 0 | W26: On time
